{
  "_id": {
    "$oid": "60720d1343dd71267de27f29"
  },
  "author_association": "MEMBER",
  "issue_url": "https://api.github.com/repos/python-trio/trio/issues/654",
  "updated_at": "2018-09-10T08:03:51Z",
  "performed_via_github_app": null,
  "html_url": "https://github.com/python-trio/trio/pull/654#issuecomment-419823783",
  "created_at": "2018-09-10T08:03:51Z",
  "id": 419823783,
  "body": "I think the coverage failure comes from https://github.com/python-trio/trio/pull/656. Maybe some kind of race condition where the coverage result of merging #656 had not been taken into account yet when computing the coverage of this PR?",
  "user": {
    "gists_url": "https://api.github.com/users/pquentin/gists{/gist_id}",
    "repos_url": "https://api.github.com/users/pquentin/repos",
    "following_url": "https://api.github.com/users/pquentin/following{/other_user}",
    "starred_url": "https://api.github.com/users/pquentin/starred{/owner}{/repo}",
    "login": "pquentin",
    "followers_url": "https://api.github.com/users/pquentin/followers",
    "type": "User",
    "url": "https://api.github.com/users/pquentin",
    "subscriptions_url": "https://api.github.com/users/pquentin/subscriptions",
    "received_events_url": "https://api.github.com/users/pquentin/received_events",
    "avatar_url": "https://avatars.githubusercontent.com/u/42327?v=4",
    "events_url": "https://api.github.com/users/pquentin/events{/privacy}",
    "html_url": "https://github.com/pquentin",
    "site_admin": false,
    "id": 42327,
    "gravatar_id": "",
    "node_id": "MDQ6VXNlcjQyMzI3",
    "organizations_url": "https://api.github.com/users/pquentin/orgs"
  },
  "url": "https://api.github.com/repos/python-trio/trio/issues/comments/419823783",
  "node_id": "MDEyOklzc3VlQ29tbWVudDQxOTgyMzc4Mw=="
}